Workbook

Sheet Tổng hợp
A1: Tháng | B1: Tổng task | C1: Task | D1: Bug | E1: Task gốc | F1: Subtask
A2: Tháng 2/2026 | B2: =COUNTA('Tháng 2'!B:B)-1 | C2: =COUNTIF('Tháng 2'!D:D,"Task") | D2: =COUNTIF('Tháng 2'!D:D,"Bug") | E2: =B2-F2 | F2: =COUNTIF('Tháng 2'!E2:E5000,"?*")
A3: Tháng 3/2026 | B3: =COUNTA('Tháng 3'!B:B)-1 | C3: =COUNTIF('Tháng 3'!D:D,"Task") | D3: =COUNTIF('Tháng 3'!D:D,"Bug") | E3: =B3-F3 | F3: =COUNTIF('Tháng 3'!E2:E5000,"?*")
A4: Tháng 4/2026 | B4: =COUNTA('Tháng 4'!B:B)-1 | C4: =COUNTIF('Tháng 4'!D:D,"Task") | D4: =COUNTIF('Tháng 4'!D:D,"Bug") | E4: =B4-F4 | F4: =COUNTIF('Tháng 4'!E2:E5000,"?*")
A5: Tháng 5/2026 | B5: =COUNTA('Tháng 5'!B:B)-1 | C5: =COUNTIF('Tháng 5'!D:D,"Task") | D5: =COUNTIF('Tháng 5'!D:D,"Bug") | E5: =B5-F5 | F5: =COUNTIF('Tháng 5'!E2:E5000,"?*")
A6: Tháng 6/2026 | B6: =COUNTA('Tháng 6'!B:B)-1 | C6: =COUNTIF('Tháng 6'!D:D,"Task") | D6: =COUNTIF('Tháng 6'!D:D,"Bug") | E6: =B6-F6 | F6: =COUNTIF('Tháng 6'!E2:E5000,"?*")
A7: Tháng 7/2026 | B7: =COUNTA('Tháng 7'!B:B)-1 | C7: =COUNTIF('Tháng 7'!D:D,"Task") | D7: =COUNTIF('Tháng 7'!D:D,"Bug") | E7: =B7-F7 | F7: =COUNTIF('Tháng 7'!E2:E5000,"?*")
A8: Tháng 8/2026 | B8: =COUNTA('Tháng 8'!B:B)-1 | C8: =COUNTIF('Tháng 8'!D:D,"Task") | D8: =COUNTIF('Tháng 8'!D:D,"Bug") | E8: =B8-F8 | F8: =COUNTIF('Tháng 8'!E2:E5000,"?*")
A9: Tháng 9/2026 | B9: =COUNTA('Tháng 9'!B:B)-1 | C9: =COUNTIF('Tháng 9'!D:D,"Task") | D9: =COUNTIF('Tháng 9'!D:D,"Bug") | E9: =B9-F9 | F9: =COUNTIF('Tháng 9'!E2:E5000,"?*")
A10: Tháng 10/2026 | B10: =COUNTA('Tháng 10'!B:B)-1 | C10: =COUNTIF('Tháng 10'!D:D,"Task") | D10: =COUNTIF('Tháng 10'!D:D,"Bug") | E10: =B10-F10 | F10: =COUNTIF('Tháng 10'!E2:E5000,"?*")
A11: Tổng | B11: =SUM(B2:B10) | C11: =SUM(C2:C10) | D11: =SUM(D2:D10) | E11: =SUM(E2:E10) | F11: =SUM(F2:F10)
A13: Nguồn: list Tech manager (space Product Development), dữ liệu CSDL tới 2026-10-06 17:52.
A14: "Ngày lên đơn" = ngày tạo task. Gồm cả subtask (cột Task cha) và bug; không gồm task đã xoá.

Sheet Tháng 2
A1: Ngày lên đơn | B1: ID | C1: Tên task | D1: Loại | E1: Task cha | F1: Trạng thái | G1: Ưu tiên | H1: App Name | I1: Task type | J1: Người làm | K1: Người tạo | L1: Sprint | M1: Start date | N1: Due date | O1: Ngày đóng | P1: Điểm | Q1: Đánh giá DEV | R1: Đánh giá Test
A2: 2026-02-02 09:36 | B2: TICKET-5154 | C2: QA Test | D2: Task | E2: 1.0.1 - Thêm Ads/ Edit UI | F2: all issue | J2: Lê Thị Dương | K2: Lê Thị Dương
A3: 2026-02-02 09:48 | B3: TICKET-5155 | C3: 79. Video bị nháy đoạn pause lúc quay | D3: Task | E3: QA Test | F3: need to be clean | G3: low | K3: Kim Ngọc
A4: 2026-02-02 10:02 | B4: TICKET-5156 | C4: 80. Luồng Export: Phần sound ở màn Edit Video và sau khi Export không khớp nhau | D4: Task | E4: QA Test | F4: done | G4: urgent | J4: Bùi Văn Tiến | K4: Kim Ngọc
A5: 2026-02-02 10:20 | B5: TICKET-5157 | C5: 81. Animation gaem survival: Sửa lại cho cừu rơi trước miếng gỗ | D5: Task | E5: QA Test | F5: done | J5: Ngọc Văn Linh | K5: Kim Ngọc
A6: 2026-02-02 10:20 | B6: TICKET-5158 | C6: Bug 1: Ứng dụng tự động chuyển sang màn hình Preview khi quay lại từ thanh điều hướng trong lúc đang quay video. | D6: Task | E6: QA Test | F6: qa - fix done | G6: high | J6: Phạm Văn Khải | K6: Lê Thị Dương
A7: 2026-02-02 10:22 | B7: TICKET-5159 | C7: Bug 2: Lỗi UI tutorial ngón tay | D7: Task | E7: QA Test | F7: qa - fix done | G7: normal | J7: Phạm Văn Khải | K7: Lê Thị Dương
A8: 2026-02-02 10:29 | B8: TICKET-5160 | C8: Bug 3: Lỗi UI btn Download trên màn Result | D8: Task | E8: QA Test | F8: qa - fix done | G8: normal | J8: Phạm Văn Khải | K8: Lê Thị Dương
A9: 2026-02-02 10:38 | B9: TICKET-5161 | C9: Gắn quảng cáo | D9: Task | E9: 1.0.1 - Add Ads/ Edit UI/ Edit flow | F9: done | J9: Ngọc Văn Linh | K9: Nguyễn Ngọc Hạnh Ngân
A10: 2026-02-02 10:38 | B10: TICKET-5162 | C10: Chỉnh sửa UI | D10: Task | E10: 1.0.1 - Add Ads/ Edit UI/ Edit flow | F10: done | J10: Ngọc Văn Linh | K10: Nguyễn Ngọc Hạnh Ngân
A11: 2026-02-02 10:47 | B11: TICKET-5163 | C11: Bug 4: Lỗi UI btn Export & Share trên tab Save màn My collection | D11: Task | E11: QA Test | F11: qa - fix done | G11: normal | J11: Nguyễn Nhật Minh | K11: Lê Thị Dương
A12: 2026-02-02 10:47 | B12: TICKET-5164 | C12: Bug 5: Crash | D12: Task | E12: QA Test | F12: qa - fix done | G12: high | J12: Nguyễn Nhật Minh | K12: Lê Thị Dương
A13: 2026-02-02 10:53 | B13: TICKET-5165 | C13: 82. Thiếu xin quyền file ở luồng download màn Profile | D13: Task | E13: QA Test | F13: done | G13: urgent | J13: Bùi Văn Tiến | K13: Kim Ngọc
A14: 2026-02-02 11:01 | B14: TICKET-5166 | C14: Bug 6: Lỗi hiển thị màn hình đen nhưng vẫn phát nhạc khi Back từ màn Camera Filter | D14: Task | E14: QA Test | F14: need to be clean | G14: urgent | J14: Nguyễn Nhật Minh | K14: Lê Thị Dương
A15: 2026-02-02 11:04 | B15: TICKET-5167 | C15: Bug 7: Lỗi hiển thị màn hình đen nhưng vẫn phát nhạc khi Back từ tab favorite trên màn My collection | D15: Task | E15: QA Test | F15: need to be clean | G15: urgent | J15: Nguyễn Nhật Minh | K15: Lê Thị Dương
A16: 2026-02-02 11:06 | B16: TICKET-5168 | C16: 1.1.3 Add tracking/Fix showrate | D16: Task | F16: ready to release | H16: Transperent wallpaper | J16: Nguyễn Nhật Minh | K16: Trần Nguyệt Ánh | L16: Sprint 14 (1/26 - 2/12) | Q16: 3
A17: 2026-02-02 11:21 | B17: TICKET-5169 | C17: 83. Gắn thiếu luồng Edit | D17: Task | E17: QA Test | F17: done | G17: urgent | J17: Bùi Văn Tiến | K17: Kim Ngọc
A18: 2026-02-02 11:23 | B18: TICKET-5170 | C18: 1.1.0 Edit UI/Add function/Fix bug/add ads/add tracking | D18: Task | F18: ready to release | H18: VPN | J18: Bùi Văn Tiến, Kim Ngọc, Ngọc Văn Linh | K18: Trần Nguyệt Ánh | L18: Sprint 15 (2/24 - 3/13) | M18: 2026-03-02 09:30 | N18: 2026-03-06 18:00
A19: 2026-02-02 11:24 | B19: TICKET-5171 | C19: Thêm chức năng rate | D19: Task | E19: 1.1.0 Edit UI/Add function/Fix bug/add ads/add tracking | F19: done | K19: Trần Nguyệt Ánh
A20: 2026-02-02 11:34 | B20: TICKET-5173 | C20: Thêm tính năng Paralax wpp | D20: Task | E20: New function/add tracking/add ads | F20: ready to progress | J20: Nguyễn Nhật Minh | K20: Trần Nguyệt Ánh
A21: 2026-02-02 11:34 | B21: TICKET-5174 | C21: Thêm tracking | D21: Task | E21: New function/add tracking/add ads | F21: ready to progress | J21: Bùi Văn Tiến | K21: Trần Nguyệt Ánh
A22: 2026-02-02 11:38 | B22: TICKET-5175 | C22: 84. Lỗi luồng back tại màn Profile, Video Trending | D22: Task | E22: QA Test | F22: done | J22: Bùi Văn Tiến | K22: Kim Ngọc
A23: 2026-02-02 11:55 | B23: TICKET-5176 | C23: 85. Crash toolbar màn Profile | D23: Task | E23: QA Test | F23: qa - cant fix | G23: urgent | J23: Bùi Văn Tiến | K23: Kim Ngọc
A24: 2026-02-02 14:16 | B24: TICKET-5177 | C24: Bug1: Thêm rate app: User click button Back/Home tại màn result => MM khi click vào nút "back"hệ thống hiển thị dialog rate trên màn home | D24: Bug | E24: QA Test | F24: done | J24: Lục Tiến Đạt | K24: Trịnh Thị Thơ
A25: 2026-02-02 14:20 | B25: TICKET-5178 | C25: Bug2: Button " No thanks" ở màn iap click 2 lần mới chuyển mà => MM : Click 1 lần chuyển màn | D25: Bug | E25: QA Test | F25: done | J25: Lục Tiến Đạt | K25: Trịnh Thị Thơ
A26: 2026-02-02 14:25 | B26: TICKET-5179 | C26: Bug3: Màn Crosshair Generator : Quảng cáo inter ở " Button Crosshair" Không qua màn . Không bật nút button lên, hay thay đổi trạng thái gì .=> MM: Quảng cáo inter xong trạng thái button thay đổi | D26: Bug | E26: QA Test | F26: done | J26: Lục Tiến Đạt | K26: Trịnh Thị Thơ
A27: 2026-02-02 15:16 | B27: TICKET-5183 | C27: Fix crash | D27: Task | E27: Dev | F27: done | K27: Nguyễn Bảo Ngọc
A28: 2026-02-02 16:33 | B28: TICKET-5195 | C28: 86. Sửa lại text author màn View video trending | D28: Task | E28: QA Test | F28: done | J28: Bùi Văn Tiến | K28: Kim Ngọc
A29: 2026-02-02 17:07 | B29: TICKET-5196 | C29: 87. Sửa lại UI | D29: Task | E29: QA Test | F29: all issue | J29: Bùi Văn Tiến | K29: Kim Ngọc
A30: 2026-02-02 17:16 | B30: TICKET-5197 | C30: 88. Luồng play game khác khi chọn content ở màn Result, Download successful | D30: Task | E30: QA Test | F30: done | G30: urgent | J30: Bùi Văn Tiến | K30: Kim Ngọc
A31: 2026-02-02 17:46 | B31: TICKET-5199 | C31: Demo core feature app mới | D31: Task | F31: pending | H31: Fun Filter | K31: Dương Thế Tài
A32: 2026-02-03 10:00 | B32: TICKET-5274 | C32: Task bổ sung: Refactor luồng dữ liệu View Content đi từ tất cả các luồng | D32: Task | E32: 1.0.1 - Thêm Ads/ Edit UI | F32: pending | K32: Nguyễn Nhật Minh | M32: 2026-02-03 09:00 | N32: 2026-02-04 12:00
A33: 2026-02-03 10:32 | B33: TICKET-5281 | C33: Bug 8: Tại màn Home không hiển thị các catagory | D33: Task | E33: QA Test | F33: qa - fix done | G33: urgent | J33: Phạm Văn Khải | K33: Lê Thị Dương
A34: 2026-02-03 10:42 | B34: TICKET-5285 | C34: Bug 1: qc category-bottom_native không reload lại khi click vào btn See more | D34: Task | E34: Bug 10: Lỗi QC | F34: qa - fix done | G34: high | J34: Phạm Văn Khải | K34: Lê Thị Dương
A35: 2026-02-03 10:57 | B35: TICKET-5287 | C35: 89. Màn Edit video: Lỗi crash khi cut video | D35: Task | E35: QA Test | F35: done | G35: urgent | J35: Bùi Văn Tiến | K35: Kim Ngọc
A36: 2026-02-03 11:20 | B36: TICKET-5293 | C36: 90. Crash màn Camera | D36: Task | E36: QA Test | F36: done | J36: Ngọc Văn Linh | K36: Kim Ngọc
A37: 2026-02-03 16:04 | B37: TICKET-5294 | C37: Bug 9: Không ghép nhạc vào video được | D37: Task | E37: QA Test | F37: qa - fix done | G37: high | J37: Phạm Văn Khải | K37: Lê Thị Dương
A38: 2026-02-04 10:08 | B38: TICKET-5314 | C38: Bug 10: Lỗi QC | D38: Task | E38: QA Test | F38: qa - fix done | K38: Lê Thị Dương
A39: 2026-02-04 10:09 | B39: TICKET-5315 | C39: Bug 11: Khi click vào QC trên popup rending, sau đó tầm 5s quay trở lại ứng dụng thì không chuyển được màn | D39: Task | E39: QA Test | F39: qa - fix done | G39: high | J39: Phạm Văn Khải | K39: Lê Thị Dương
A40: 2026-02-04 10:24 | B40: TICKET-5316 | C40: Bug 12: Tỷ lệ show qc Splash-afterinter là thấp khoàng 50% | D40: Task | E40: QA Test | F40: all issue | G40: high | J40: Phạm Văn Khải | K40: Lê Thị Dương
...

Sheet Tháng 3
A1: Ngày lên đơn | B1: ID | C1: Tên task | D1: Loại | E1: Task cha | F1: Trạng thái | G1: Ưu tiên | H1: App Name | I1: Task type | J1: Người làm | K1: Người tạo | L1: Sprint | M1: Start date | N1: Due date | O1: Ngày đóng | P1: Điểm | Q1: Đánh giá DEV | R1: Đánh giá Test
A2: 2026-03-02 11:58 | B2: TICKET-5630 | C2: Bug 1: Quảng cáo dưới chân màn hình XAP & APK Manager không hiển thị sau khi thu hồi quyền hệ thống | D2: Task | E2: QA Test | F2: qa - need fix | G2: high | J2: Nguyễn Nhật Minh | K2: Lê Thị Dương
A3: 2026-03-02 13:44 | B3: TICKET-5631 | C3: Bug 2: Tại vị trí quảng cáo language2.1_native( có bật) nhưng không show được quảng cáo | D3: Task | E3: QA Test | F3: need to be clean | G3: normal | J3: Nguyễn Nhật Minh | K3: Lê Thị Dương
A4: 2026-03-02 13:44 | B4: TICKET-5632 | C4: Bug 3: Khi click vào qc Language 1.1 sau đó quay trở lại ứng dụng=> không show qc Language 2.2 | D4: Task | E4: QA Test | F4: done | G4: normal | J4: Nguyễn Nhật Minh | K4: Lê Thị Dương
A5: 2026-03-02 14:32 | B5: TICKET-5634 | C5: Bug 4: Qc QC native inline tại tab zip extractor (bật) không loading được quảng cáo | D5: Task | E5: QA Test | F5: need to be clean | G5: normal | J5: Nguyễn Nhật Minh | K5: Lê Thị Dương
A6: 2026-03-02 17:16 | B6: TICKET-5635 | C6: Bug 5: Tại màn XAPK & APK Manager-> Nhấn btn Install-> bắn qc inter-> tắt qc Inter=> Trở về màn XAP Manager & không hiển thị dialog hệ thống " "Bạn có muốn cài đặt ứng dụng này không"?" | D6: Task | E6: QA Test | F6: done | G6: high | J6: Nguyễn Nhật Minh | K6: Lê Thị Dương
A7: 2026-03-02 17:53 | B7: TICKET-5636 | C7: Tap vào ... của màn music không chọn được chức năng. Xem ảnh => MM : Click sử dụng được chức năng của dấu ... | D7: Bug | E7: QA Test | F7: done | J7: Nguyễn Nhật Minh | K7: Trịnh Thị Thơ
A8: 2026-03-03 14:40 | B8: TICKET-5648 | C8: QA Test | D8: Task | E8: Thêm luồng inter sang preload | F8: done | J8: Lê Thị Dương | K8: Lê Thị Dương
A9: 2026-03-03 14:43 | B9: TICKET-5650 | C9: Bug 1: Không chuyển màn sau khi tắt quảng cáo Interstitial khi chọn các tính năng trong Famous Place. | D9: Task | E9: QA Test | F9: done | G9: high | J9: Phạm Văn Khải | K9: Lê Thị Dương
A10: 2026-03-03 14:43 | B10: TICKET-5651 | C10: 1. Gif splash không hoạt động | D10: Task | E10: QA test | F10: done | K10: Kim Ngọc
A11: 2026-03-03 14:50 | B11: TICKET-5652 | C11: Bug 2: Lỗi UI dialog IAP tại màn Home | D11: Task | E11: QA Test | F11: qa - fix done | G11: high | J11: Phạm Văn Khải | K11: Lê Thị Dương
A12: 2026-03-03 15:04 | B12: TICKET-5653 | C12: Bug 3: Crash | D12: Task | E12: QA Test | F12: done | G12: urgent | J12: Phạm Văn Khải | K12: Lê Thị Dương
A13: 2026-03-03 16:19 | B13: TICKET-5655 | C13: Bug 4: Tắt hết tất cả vị trí Inter trên màn Home đi nhưng vẫn show quy tắc hiển thị dialog IAP sau bao nhiêu inter | D13: Task | E13: QA Test | F13: done | G13: high | J13: Phạm Văn Khải | K13: Lê Thị Dương
A14: 2026-03-03 16:20 | B14: TICKET-5656 | C14: Bug 5: Mất hình ảnh trên dialog Watch | D14: Task | E14: QA Test | F14: done | G14: normal | J14: Phạm Văn Khải | K14: Lê Thị Dương
A15: 2026-03-04 09:56 | B15: TICKET-5659 | C15: Fix UI | D15: Task | E15: Fix UI/Edit IAP | F15: all issue | K15: Nguyễn Ngọc Hạnh Ngân
A16: 2026-03-04 09:56 | B16: TICKET-5660 | C16: Edit/Update IAP | D16: Task | E16: Fix UI/Edit IAP | F16: all issue | K16: Nguyễn Ngọc Hạnh Ngân
A17: 2026-03-04 10:27 | B17: TICKET-5661 | C17: 2. Nav sai màn | D17: Task | E17: QA test | F17: done | K17: Kim Ngọc
A18: 2026-03-04 10:36 | B18: TICKET-5662 | C18: 1.0.0 - Speaker Cleaner 2 | D18: Task | F18: ready to release | H18: Speak2 | K18: Phạm Văn Khải
A19: 2026-03-04 10:37 | B19: TICKET-5663 | C19: Màn Splash | D19: Task | E19: 1.0.0 - Speaker Cleaner 2 R1 | F19: ready to qa-testing | J19: Bùi Văn Tiến | K19: Phạm Văn Khải | M19: 2026-03-04 13:30 | N19: 2026-03-04 15:00
A20: 2026-03-04 10:38 | B20: TICKET-5664 | C20: Màn Language | D20: Task | E20: 1.0.0 - Speaker Cleaner 2 R1 | F20: ready to qa-testing | J20: Bùi Văn Tiến | K20: Phạm Văn Khải | M20: 2026-03-04 15:00 | N20: 2026-03-04 18:00
A21: 2026-03-04 10:38 | B21: TICKET-5665 | C21: Màn Applying Language | D21: Task | E21: 1.0.0 - Speaker Cleaner 2 R1 | F21: ready to qa-testing | J21: Bùi Văn Tiến | K21: Phạm Văn Khải | M21: 2026-03-05 09:30 | N21: 2026-03-05 12:00
A22: 2026-03-04 10:38 | B22: TICKET-5666 | C22: Màn Onboarding | D22: Task | E22: 1.0.0 - Speaker Cleaner 2 R1 | F22: ready to qa-testing | J22: Bùi Văn Tiến | K22: Phạm Văn Khải | M22: 2026-03-05 13:30 | N22: 2026-03-05 16:00
A23: 2026-03-04 10:38 | B23: TICKET-5667 | C23: Màn Setting | D23: Task | E23: 1.0.0 - Speaker Cleaner 2 R1 | F23: ready to qa-testing | J23: Bùi Văn Tiến | K23: Phạm Văn Khải | M23: 2026-03-05 16:00 | N23: 2026-03-05 18:00
A24: 2026-03-04 10:38 | B24: TICKET-5668 | C24: Màn Home | D24: Task | E24: 1.0.0 - Speaker Cleaner 2 R1 | F24: ready to qa-testing | J24: Bùi Văn Tiến | K24: Phạm Văn Khải | M24: 2026-03-06 09:30 | N24: 2026-03-06 12:00
A25: 2026-03-04 10:39 | B25: TICKET-5669 | C25: Màn List Mode Clean Type | D25: Task | E25: 1.0.0 - Speaker Cleaner 2 R1 | F25: ready to qa-testing | J25: Phạm Văn Khải | K25: Phạm Văn Khải
A26: 2026-03-04 10:40 | B26: TICKET-5670 | C26: Màn Setup Guide | D26: Task | E26: 1.0.0 - Speaker Cleaner 2 R1 | F26: ready to qa-testing | J26: Phạm Văn Khải | K26: Phạm Văn Khải
A27: 2026-03-04 10:57 | B27: TICKET-5671 | C27: Màn Cleaning Phone | D27: Task | E27: 1.0.0 - Speaker Cleaner 2 R2 | F27: ready to qa-testing | J27: Phạm Văn Khải | K27: Phạm Văn Khải
A28: 2026-03-04 10:58 | B28: TICKET-5672 | C28: Màn Speaker Refreshed | D28: Task | E28: 1.0.0 - Speaker Cleaner 2 R2 | F28: ready to qa-testing | J28: Bùi Văn Tiến | K28: Phạm Văn Khải | M28: 2026-03-16 09:00 | N28: 2026-03-16 18:00
A29: 2026-03-04 10:58 | B29: TICKET-5673 | C29: Màn Success | D29: Task | E29: 1.0.0 - Speaker Cleaner 2 R2 | F29: ready to qa-testing | J29: Phạm Văn Khải | K29: Phạm Văn Khải | M29: 2026-03-11 09:30 | N29: 2026-03-11 12:00
A30: 2026-03-04 10:59 | B30: TICKET-5674 | C30: Màn Clean Custom | D30: Task | E30: 1.0.0 - Speaker Cleaner 2 R1 | F30: ready to qa-testing | J30: Bùi Văn Tiến | K30: Phạm Văn Khải | M30: 2026-03-06 15:00 | N30: 2026-03-10 18:00
A31: 2026-03-04 11:02 | B31: TICKET-5675 | C31: UI | D31: Task | E31: Màn List Mode Clean Type | F31: ready to qa-testing | J31: Phạm Văn Khải | K31: Phạm Văn Khải
A32: 2026-03-04 11:02 | B32: TICKET-5676 | C32: Setup Database | D32: Task | E32: Màn List Mode Clean Type | F32: ready to qa-testing | J32: Phạm Văn Khải | K32: Phạm Văn Khải
A33: 2026-03-04 11:03 | B33: TICKET-5677 | C33: Logic get, show data | D33: Task | E33: Màn List Mode Clean Type | F33: ready to qa-testing | J33: Phạm Văn Khải | K33: Phạm Văn Khải
A34: 2026-03-04 11:05 | B34: TICKET-5678 | C34: UI | D34: Task | E34: Màn Splash | F34: in progress | K34: Bùi Văn Tiến | M34: 2026-03-04 13:30 | N34: 2026-03-04 16:00
A35: 2026-03-04 11:05 | B35: TICKET-5679 | C35: UI | D35: Task | E35: Màn Language | F35: all issue | K35: Bùi Văn Tiến
A36: 2026-03-04 11:05 | B36: TICKET-5680 | C36: LOGIC | D36: Task | E36: Màn Language | F36: all issue | K36: Bùi Văn Tiến
A37: 2026-03-04 11:05 | B37: TICKET-5681 | C37: UI | D37: Task | E37: Màn Applying Language | F37: all issue | K37: Bùi Văn Tiến
A38: 2026-03-04 11:05 | B38: TICKET-5682 | C38: LOGIC | D38: Task | E38: Màn Applying Language | F38: all issue | K38: Bùi Văn Tiến
A39: 2026-03-04 11:05 | B39: TICKET-5683 | C39: UI | D39: Task | E39: Màn Onboarding | F39: all issue | K39: Bùi Văn Tiến
A40: 2026-03-04 11:05 | B40: TICKET-5684 | C40: LOGIC | D40: Task | E40: Màn Onboarding | F40: all issue | K40: Bùi Văn Tiến
...

Sheet Tháng 4
A1: Ngày lên đơn | B1: ID | C1: Tên task | D1: Loại | E1: Task cha | F1: Trạng thái | G1: Ưu tiên | H1: App Name | I1: Task type | J1: Người làm | K1: Người tạo | L1: Sprint | M1: Start date | N1: Due date | O1: Ngày đóng | P1: Điểm | Q1: Đánh giá DEV | R1: Đánh giá Test
A2: 2026-04-01 10:56 | B2: TICKET-7309 | C2: 1.0.1 - Add ads | D2: Task | F2: done | H2: Speak2 | J2: Bùi Văn Tiến, Kim Ngọc, Lục Tiến Đạt | K2: Nguyễn Ngọc Hạnh Ngân | L2: Sprint 17 (4/2 - 4/14) | N2: 2026-04-09 18:00
A3: 2026-04-01 11:00 | B3: TICKET-7310 | C3: Edit UI và logic màn language | D3: Task | E3: 1.0.3 - Edit ads/ Add tracking/Edit UI | F3: done | J3: Ngọc Văn Linh | K3: Nguyễn Ngọc Hạnh Ngân | P3: 1
A4: 2026-04-01 11:01 | B4: TICKET-7311 | C4: 1.0.6 - Fix crash/ Add tracking | D4: Task | F4: ready to progress | H4: metal detector | K4: Nguyễn Ngọc Hạnh Ngân
A5: 2026-04-01 11:02 | B5: TICKET-7314 | C5: 1.1.6 - Fix luồng/Edit ads/Add ads/ Edit UI | D5: Task | F5: ready to release | H5: sattelite | J5: Lục Tiến Đạt, Nguyễn Nhật Minh, Trịnh Thị Thơ | K5: Nguyễn Ngọc Hạnh Ngân | L5: Sprint 18 (4/17 - 4/29), Sprint 19 (5/6 - 5/20) | N5: 2026-05-06 04:00
A6: 2026-04-01 11:02 | B6: TICKET-7315 | C6: Fix luồng màn language | D6: Task | E6: 1.1.6 - Fix luồng/Edit ads/Add ads/ Edit UI | F6: done | K6: Nguyễn Ngọc Hạnh Ngân
A7: 2026-04-01 11:02 | B7: TICKET-7316 | C7: Edit qc naive after inter | D7: Task | E7: 1.1.6 - Fix luồng/Edit ads/Add ads/ Edit UI | F7: done | K7: Nguyễn Ngọc Hạnh Ngân
A8: 2026-04-01 11:21 | B8: TICKET-7317 | C8: 9. Lỗi Ui màn search street view map | D8: Task | E8: Bug 1: Lỗi UI các màn liên quan đến màn Street View 360 | F8: done | G8: normal | J8: Bùi Văn Tiến | K8: Lê Thị Dương
A9: 2026-04-01 11:22 | B9: TICKET-7318 | C9: 10. Lỗi Ui màn search street view map khi không có mạng | D9: Task | E9: Bug 1: Lỗi UI các màn liên quan đến màn Street View 360 | F9: done | G9: normal | J9: Bùi Văn Tiến | K9: Lê Thị Dương
A10: 2026-04-01 11:26 | B10: TICKET-7319 | C10: 11. Trên tất cả các Popup Watch đều thiếu biểu tượng lịch | D10: Task | E10: Bug 1: Lỗi UI các màn liên quan đến màn Street View 360 | F10: done | G10: normal | J10: Bùi Văn Tiến | K10: Lê Thị Dương
A11: 2026-04-02 10:06 | B11: TICKET-7320 | C11: QA Test | D11: Task | E11: MVP 1.0.0 - live video 2 R1 | F11: qa - testing | K11: Lục Tiến Đạt
A12: 2026-04-02 10:41 | B12: TICKET-7321 | C12: Bug 7: Danh sách "Famous Place" không tự động đẩy item đã xem xuống cuối hàng ( Đối với tất cả các màn trên tính năng Street View 360) | D12: Task | E12: QA Test | F12: done | G12: normal | J12: Nguyễn Nhật Minh | K12: Lê Thị Dương
A13: 2026-04-02 11:18 | B13: TICKET-7322 | C13: Bug 8: Crash | D13: Task | E13: QA Test | F13: done | G13: urgent | J13: Nguyễn Nhật Minh | K13: Lê Thị Dương
A14: 2026-04-02 11:32 | B14: TICKET-7323 | C14: Bug 9: Trên màn Street View 360 không hiển thị tháng/năm ( Lỗi trên tất cả các màn) | D14: Task | E14: QA Test | F14: done | G14: normal | J14: Nguyễn Nhật Minh | K14: Lê Thị Dương
A15: 2026-04-02 14:31 | B15: TICKET-7330 | C15: Bug 10: Sai điều hướng ( Lỗi bị lặp lại ở phần Map & History) | D15: Task | E15: QA Test | F15: done | G15: normal | J15: Nguyễn Nhật Minh | K15: Lê Thị Dương
A16: 2026-04-02 15:19 | B16: TICKET-7331 | C16: Bug 11: Màn hình Map hiển thị sai địa điểm cũ sau khi Back từ màn Street View 360 (Dữ liệu tìm kiếm mới bị ghi đè bởi dữ liệu cũ). | D16: Task | E16: QA Test | F16: done | G16: high | J16: Nguyễn Nhật Minh | K16: Lê Thị Dương
A17: 2026-04-02 15:21 | B17: TICKET-7332 | C17: Fix crash | D17: Task | E17: 1.0.6 - Fix crash/ Add tracking | F17: ready to progress | K17: Trần Nguyệt Ánh
A18: 2026-04-02 15:21 | B18: TICKET-7333 | C18: Add tracking | D18: Task | E18: 1.0.6 - Fix crash/ Add tracking | F18: ready to progress | K18: Trần Nguyệt Ánh
A19: 2026-04-03 14:26 | B19: TICKET-7335 | C19: Task Bổ Sung | D19: Task | E19: MVP 1.0.0 - live video 2 R2 | F19: ready to qa-testing | J19: Nguyễn Nhật Minh | K19: Nguyễn Nhật Minh
A20: 2026-04-03 14:27 | B20: TICKET-7336 | C20: Bổ sung Map + Pin Point + Dialog cho 3 maps 3 feature | D20: Task | E20: Task Bổ Sung | F20: ready to qa-testing | K20: Nguyễn Nhật Minh
A21: 2026-04-03 14:27 | B21: TICKET-7337 | C21: Dialog Maps | D21: Task | E21: Bổ sung Map + Pin Point + Dialog cho 3 maps 3 feature | F21: all issue | K21: Nguyễn Nhật Minh
A22: 2026-04-03 14:28 | B22: TICKET-7338 | C22: UI | D22: Task | E22: Dialog Maps | F22: all issue | K22: Nguyễn Nhật Minh
A23: 2026-04-03 14:28 | B23: TICKET-7339 | C23: Logic | D23: Task | E23: Dialog Maps | F23: all issue | K23: Nguyễn Nhật Minh
A24: 2026-04-03 14:28 | B24: TICKET-7340 | C24: Logic map chung | D24: Task | E24: Bổ sung Map + Pin Point + Dialog cho 3 maps 3 feature | F24: all issue | K24: Nguyễn Nhật Minh
A25: 2026-04-03 14:32 | B25: TICKET-7343 | C25: Bổ sung UI + Logic Adapter thay đổi location | D25: Task | E25: Phone Locator/ Màn map | F25: ready to qa-testing | K25: Nguyễn Nhật Minh
A26: 2026-04-06 14:03 | B26: TICKET-7458 | C26: MVP 1.0.0 - Wallpaper 2 | D26: Task | F26: ready to release | H26: wallpaper | K26: Ngọc Văn Linh
A27: 2026-04-06 14:28 | B27: TICKET-7469 | C27: Bug 1: UI Các màn | D27: Task | E27: QA Test | F27: done | G27: normal | J27: Nguyễn Nhật Minh | K27: Lê Thị Dương
A28: 2026-04-06 14:28 | B28: TICKET-7470 | C28: Bug 2: Trên Popup mất kết nối Internet click vào khoảng trắng đóng dialog lại | D28: Task | E28: QA Test | F28: done | G28: normal | J28: Nguyễn Nhật Minh | K28: Lê Thị Dương
A29: 2026-04-06 14:32 | B29: TICKET-7471 | C29: Bug 3: Tìm kiếm số điện thoại không hợp lệ không được lưu vào Lịch sử (History) | D29: Task | E29: QA Test | F29: done | G29: high | J29: Nguyễn Nhật Minh | K29: Lê Thị Dương
A30: 2026-04-06 14:38 | B30: TICKET-7472 | C30: Bug 4: Khi click vào quốc gia bất kỳ, mã quốc gia đó không được đẩy lên đầu danh sách | D30: Task | E30: QA Test | F30: done | G30: high | J30: Nguyễn Nhật Minh | K30: Lê Thị Dương
A31: 2026-04-06 14:47 | B31: TICKET-7473 | C31: QA: | D31: Task | E31: 1.1.1 Fix bug | F31: all issue | K31: Trịnh Thị Thơ
A32: 2026-04-06 14:49 | B32: TICKET-7474 | C32: Bug1: Text UI phần Tutorial khác với bản build xem ảnh. MM sửa đúng theo link figma: https://www.figma.com/design/NeCET4LMwkS0tdWUAvsYtc/PS-Remote_UI?node-id=10217-7908&t=5EY9fETA2qMaBPul-0 | D32: Bug | E32: QA: | F32: done | J32: Phạm Văn Khải | K32: Trịnh Thị Thơ
A33: 2026-04-06 15:04 | B33: TICKET-7476 | C33: Bug 5: Mã quốc gia không theo mặc định của ngôn ngữ máy | D33: Task | E33: QA Test | F33: done | G33: high | J33: Nguyễn Nhật Minh | K33: Lê Thị Dương
A34: 2026-04-06 15:11 | B34: TICKET-7477 | C34: Bug 6: Hệ thống ko trả về dữ liệu khi nhập số điện thoại tìm kiếm có chứa đầu số | D34: Task | E34: QA Test | F34: done | G34: high | J34: Nguyễn Nhật Minh | K34: Lê Thị Dương
A35: 2026-04-06 15:11 | B35: TICKET-7478 | C35: Bug 7: Trên Popup miễn trừ trách nhiêm, click vào khoảng trắng, đóng dialog lại | D35: Task | E35: QA Test | F35: done | G35: normal | J35: Nguyễn Nhật Minh | K35: Lê Thị Dương
A36: 2026-04-06 15:31 | B36: TICKET-7479 | C36: Bug2: Thay đổi luồng khi Search Console thất bại/ Device không có internet/ Đăng ký Console bằng Host IP thành công: | D36: Bug | E36: QA: | F36: done | J36: Phạm Văn Khải | K36: Trịnh Thị Thơ
A37: 2026-04-06 15:46 | B37: TICKET-7480 | C37: Bug 8: Sai điều hướng khi click back từ màn History của tính năng Phone Locator | D37: Task | E37: QA Test | F37: done | G37: high | J37: Nguyễn Nhật Minh | K37: Lê Thị Dương
A38: 2026-04-06 15:51 | B38: TICKET-7481 | C38: Bug 9: Tại màn Phone Locator click back bị sai điều hướng | D38: Task | E38: QA Test | F38: done | G38: high | J38: Nguyễn Nhật Minh | K38: Lê Thị Dương
A39: 2026-04-06 15:51 | B39: TICKET-7482 | C39: Bug 10: Quốc gia được chọn ko được ưu tiên đẩy lên đầu danh sách | D39: Task | E39: QA Test | F39: done | G39: normal | J39: Nguyễn Nhật Minh | K39: Lê Thị Dương
A40: 2026-04-06 15:55 | B40: TICKET-7483 | C40: Splash | D40: Task | E40: MVP 1.0.0 - Wallpaper 2 R1 | F40: ready to qa-testing | K40: Ngọc Văn Linh
...

Sheet Tháng 5
A1: Ngày lên đơn | B1: ID | C1: Tên task | D1: Loại | E1: Task cha | F1: Trạng thái | G1: Ưu tiên | H1: App Name | I1: Task type | J1: Người làm | K1: Người tạo | L1: Sprint | M1: Start date | N1: Due date | O1: Ngày đóng | P1: Điểm | Q1: Đánh giá DEV | R1: Đánh giá Test
A2: 2026-05-04 09:43 | B2: TICKET-10693 | C2: 3. Không được close dialog khi click ngoài khu vực dialog/ reopen khi đưa app vào background | D2: Task | E2: QA Test | F2: done | K2: Kim Ngọc
A3: 2026-05-04 10:03 | B3: TICKET-10699 | C3: 4. Lỗi download content | D3: Task | E3: QA Test | F3: done | G3: urgent | K3: Kim Ngọc
A4: 2026-05-04 10:09 | B4: TICKET-10700 | C4: 5. Lỗi không apply wallpaper với một số content | D4: Task | E4: QA Test | F4: done | G4: urgent | K4: Kim Ngọc
A5: 2026-05-04 10:18 | B5: TICKET-10701 | C5: 6. Sau khi apply wallpaper lần 1 thì apply lần 2 không show màn Preview và Apply Successfull | D5: Task | E5: QA Test | F5: done | G5: urgent | K5: Kim Ngọc
A6: 2026-05-04 12:04 | B6: TICKET-10733 | C6: MO test | D6: Task | E6: 1.0.1 - Add ads/Edit UI | F6: done | J6: Nguyễn Ngọc Hạnh Ngân, Nguyễn Nhật Minh, Trịnh Thị Thơ | K6: Nguyễn Ngọc Hạnh Ngân
A7: 2026-05-04 12:04 | B7: TICKET-10734 | C7: Lỗi crash | D7: Task | E7: MO test | F7: done | K7: Nguyễn Ngọc Hạnh Ngân
A8: 2026-05-04 12:04 | B8: TICKET-10735 | C8: Kích thước quảng cáo native full sau inter đang không full toàn màn hình | D8: Task | E8: MO test | F8: done | K8: Nguyễn Ngọc Hạnh Ngân
A9: 2026-05-04 12:05 | B9: TICKET-10736 | C9: Thay đổi luồng xin quyền chức năng number search | D9: Task | E9: 1.0.1 - Add ads/Edit UI | F9: done | K9: Nguyễn Ngọc Hạnh Ngân
A10: 2026-05-04 12:05 | B10: TICKET-10737 | C10: Thay đổi luồng xin quyền chức năng live video/360 view | D10: Task | E10: 1.0.1 - Add ads/Edit UI | F10: done | K10: Nguyễn Ngọc Hạnh Ngân
A11: 2026-05-04 17:57 | B11: TICKET-11078 | C11: Nghiên cứu kỹ thuật và demo tính năng ứng dụng | D11: Task | F11: done | H11: Game Emulator | K11: Dương Thế Tài | L11: Sprint 19 (5/6 - 5/20) | M11: 2026-05-13 09:00 | N11: 2026-05-18 18:00
A12: 2026-05-04 18:10 | B12: TICKET-11084 | C12: Check lỗi tắt toàn bộ luồng onboarding nhưng vẫn hiển thị Onboard 1 | D12: Task | F12: all issue | H12: Nhiều App | K12: Nguyễn Ngọc Hạnh Ngân
A13: 2026-05-04 18:10 | B13: TICKET-11085 | C13: App lock | D13: Task | E13: Check lỗi tắt toàn bộ luồng onboarding nhưng vẫn hiển thị Onboard 1 | F13: all issue | K13: Nguyễn Ngọc Hạnh Ngân
A14: 2026-05-04 18:10 | B14: TICKET-11086 | C14: Color phone | D14: Task | E14: Check lỗi tắt toàn bộ luồng onboarding nhưng vẫn hiển thị Onboard 1 | F14: all issue | K14: Nguyễn Ngọc Hạnh Ngân
A15: 2026-05-04 18:10 | B15: TICKET-11087 | C15: Pet translator | D15: Task | E15: Check lỗi tắt toàn bộ luồng onboarding nhưng vẫn hiển thị Onboard 1 | F15: all issue | K15: Nguyễn Ngọc Hạnh Ngân
A16: 2026-05-04 18:10 | B16: TICKET-11088 | C16: Fake call | D16: Task | E16: Check lỗi tắt toàn bộ luồng onboarding nhưng vẫn hiển thị Onboard 1 | F16: all issue | K16: Nguyễn Ngọc Hạnh Ngân
A17: 2026-05-04 18:11 | B17: TICKET-11089 | C17: Fluid wallpaper | D17: Task | E17: Check lỗi tắt toàn bộ luồng onboarding nhưng vẫn hiển thị Onboard 1 | F17: all issue | K17: Nguyễn Ngọc Hạnh Ngân
A18: 2026-05-04 18:11 | B18: TICKET-11090 | C18: Game mode | D18: Task | E18: Check lỗi tắt toàn bộ luồng onboarding nhưng vẫn hiển thị Onboard 1 | F18: all issue | K18: Nguyễn Ngọc Hạnh Ngân
A19: 2026-05-04 18:11 | B19: TICKET-11091 | C19: Gun challenge | D19: Task | E19: Check lỗi tắt toàn bộ luồng onboarding nhưng vẫn hiển thị Onboard 1 | F19: done | K19: Nguyễn Ngọc Hạnh Ngân
A20: 2026-05-04 18:11 | B20: TICKET-11092 | C20: Number locator | D20: Task | E20: Check lỗi tắt toàn bộ luồng onboarding nhưng vẫn hiển thị Onboard 1 | F20: all issue | K20: Nguyễn Ngọc Hạnh Ngân
A21: 2026-05-04 18:11 | B21: TICKET-11093 | C21: Number tracker | D21: Task | E21: Check lỗi tắt toàn bộ luồng onboarding nhưng vẫn hiển thị Onboard 1 | F21: all issue | K21: Nguyễn Ngọc Hạnh Ngân
A22: 2026-05-04 18:11 | B22: TICKET-11094 | C22: Satellite | D22: Task | E22: Check lỗi tắt toàn bộ luồng onboarding nhưng vẫn hiển thị Onboard 1 | F22: all issue | K22: Nguyễn Ngọc Hạnh Ngân
A23: 2026-05-04 18:11 | B23: TICKET-11095 | C23: Spin wheel | D23: Task | E23: Check lỗi tắt toàn bộ luồng onboarding nhưng vẫn hiển thị Onboard 1 | F23: all issue | K23: Nguyễn Ngọc Hạnh Ngân
A24: 2026-05-04 18:11 | B24: TICKET-11096 | C24: Voice lock | D24: Task | E24: Check lỗi tắt toàn bộ luồng onboarding nhưng vẫn hiển thị Onboard 1 | F24: all issue | K24: Nguyễn Ngọc Hạnh Ngân
A25: 2026-05-05 09:51 | B25: TICKET-11106 | C25: Add ads/ Edit UI | D25: Task | F25: ready to release | H25: Prank sound | J25: Ngọc Văn Linh, Nguyễn Tuyết Oanh | K25: Nguyễn Ngọc Hạnh Ngân | L25: Sprint 1 (5/22 - 6/5)
A26: 2026-05-05 09:51 | B26: TICKET-12507 | C26: 1.2.8 Add ads/ Edit UI/Move store | D26: Task | F26: done | H26: FlashCall | J26: Bùi Văn Tiến, Linh Đặng | K26: Nguyễn Ngọc Hạnh Ngân | L26: Sprint 2 (6/5 - 6/19)
A27: 2026-05-05 10:30 | B27: TICKET-11107 | C27: Edit luồng language | D27: Task | E27: 1.0.7 Edit feature/Add rate | F27: done | J27: Lục Tiến Đạt | K27: Nguyễn Ngọc Hạnh Ngân | P27: 2
A28: 2026-05-05 13:39 | B28: TICKET-11109 | C28: 1.0.3 - Edit ads/ Edit luồng | D28: Task | F28: ready to release | H28: AR Dog | J28: Ngọc Văn Linh, Trịnh Thị Thơ | K28: Nguyễn Ngọc Hạnh Ngân | L28: Sprint 1 (5/22 - 6/5) | M28: 2026-05-11 13:30 | N28: 2026-05-12 18:00
A29: 2026-05-05 13:39 | B29: TICKET-11110 | C29: Edit ads | D29: Task | E29: 1.0.3 - Edit ads/ Edit luồng | F29: done | J29: Ngọc Văn Linh | K29: Nguyễn Ngọc Hạnh Ngân | P29: 4
A30: 2026-05-05 13:39 | B30: TICKET-11111 | C30: Edit luồng | D30: Task | E30: 1.0.3 - Edit ads/ Edit luồng | F30: pending | J30: Ngọc Văn Linh | K30: Nguyễn Ngọc Hạnh Ngân | P30: 3
A31: 2026-05-05 14:42 | B31: TICKET-11112 | C31: MVP 1.0.0 - Wallpaper 2 R2 | D31: Task | E31: MVP 1.0.0 - Wallpaper 2 | F31: ready to release | H31: wallpaper | J31: Bùi Văn Tiến, Kim Ngọc | K31: Lục Tiến Đạt | L31: Sprint 19 (5/6 - 5/20) | N31: 2026-05-14 18:00
A32: 2026-05-05 17:10 | B32: TICKET-11116 | C32: Update module IAP | D32: Task | E32: 1.0.9 - Add ads/Edit UI/Edit luồng | F32: done | K32: Nguyễn Ngọc Hạnh Ngân
A33: 2026-05-06 09:09 | B33: TICKET-11167 | C33: 2. Bỏ button Back ở màn IAP | D33: Task | E33: QA Test | F33: done | J33: Lục Tiến Đạt | K33: Kim Ngọc
A34: 2026-05-06 09:27 | B34: TICKET-11180 | C34: 3. Fix qc redust_list-next load tại màn dustCleaningMultiLevelFragment | D34: Task | E34: QA Test | F34: done | K34: Kim Ngọc
A35: 2026-05-06 09:40 | B35: TICKET-11182 | C35: QA testing: | D35: Bug | E35: 1.0.0 MVP version R2 | F35: qa - need fix | J35: Trần Đức An | K35: Trịnh Thị Thơ
A36: 2026-05-06 09:46 | B36: TICKET-11183 | C36: Bug1: Màn Enable Accessibility: thiếu icon "See Tutorial" (xem ảnh đính kèm) | D36: Bug | E36: I. Bug xin quyền | F36: done | J36: Trần Đức An | K36: Trịnh Thị Thơ
A37: 2026-05-06 09:49 | B37: TICKET-11184 | C37: 4. Qc cleanningdust startload ngay sau khi show (isPreLoad = false) | D37: Task | E37: QA Test | F37: done | K37: Kim Ngọc
A38: 2026-05-06 09:57 | B38: TICKET-11185 | C38: 5. Sửa load qc cleanningdust | D38: Task | E38: QA Test | F38: done | K38: Kim Ngọc
A39: 2026-05-06 10:00 | B39: TICKET-11186 | C39: 6. Close qc reward tabmanual_dust_max thì lại show inter | D39: Task | E39: QA Test | F39: done | K39: Kim Ngọc
A40: 2026-05-06 10:07 | B40: TICKET-11187 | C40: 7. Qc cleanningdust-end load lại sau khi show | D40: Task | E40: QA Test | F40: need to be clean | K40: Kim Ngọc
...

Sheet Tháng 6
A1: Ngày lên đơn | B1: ID | C1: Tên task | D1: Loại | E1: Task cha | F1: Trạng thái | G1: Ưu tiên | H1: App Name | I1: Task type | J1: Người làm | K1: Người tạo | L1: Sprint | M1: Start date | N1: Due date | O1: Ngày đóng | P1: Điểm | Q1: Đánh giá DEV | R1: Đánh giá Test
A2: 2026-06-01 09:47 | B2: TICKET-13073 | C2: 36. view-wlp_between_native: Sửa lại UI | D2: Task | E2: Đã fix | F2: done | J2: Lục Tiến Đạt | K2: Kim Ngọc
A3: 2026-06-01 10:05 | B3: TICKET-13074 | C3: Bug 33. Chưa check trùng tên khi tạo config mới | D3: Bug | E3: IV. Tính năng Synchronized Clicking | F3: done | J3: Trần Đức An | K3: Linh Đặng
A4: 2026-06-01 10:25 | B4: TICKET-13075 | C4: 37. Sai luồng khi ấn Back ở màn Apply của device | D4: Task | E4: Đã fix | F4: done | J4: Bùi Văn Tiến | K4: Kim Ngọc
A5: 2026-06-01 10:29 | B5: TICKET-13076 | C5: BUg 34. Với config đã liên kết app, khi chỉ còn 1 điểm duy nhất, nhấn - k hiện cảnh báo j và có thể trừ hết các điểm | D5: Bug | E5: IV. Tính năng Synchronized Clicking | F5: done | G5: low | J5: Trần Đức An | K5: Linh Đặng
A6: 2026-06-01 10:35 | B6: TICKET-13077 | C6: Bug 35. Sai text hiển thị trong tutorial | D6: Bug | E6: IV. Tính năng Synchronized Clicking | F6: done | G6: normal | J6: Trần Đức An | K6: Linh Đặng
A7: 2026-06-01 10:36 | B7: TICKET-13078 | C7: QA Testing | D7: Task | E7: Add ads/ Edit UI | F7: done | K7: Nguyễn Tuyết Oanh
A8: 2026-06-01 10:37 | B8: TICKET-13079 | C8: 1. Edit UI/ luồng | D8: Task | E8: QA Testing | F8: done | K8: Nguyễn Tuyết Oanh
A9: 2026-06-01 10:47 | B9: TICKET-13085 | C9: Bug 42. Sai text hiển thị trong tutorial | D9: Bug | E9: III. Tính năng: Single-Target Clicker | F9: done | G9: normal | J9: Trần Đức An | K9: Linh Đặng
A10: 2026-06-01 10:52 | B10: TICKET-13086 | C10: Bug 29. Sai text hiển thị trong tutorial | D10: Bug | E10: V. Multi- action scripting | F10: done | G10: normal | J10: Trần Đức An | K10: Linh Đặng
A11: 2026-06-01 11:13 | B11: TICKET-13087 | C11: Add rate/add feature/edit database | D11: Task | F11: ready to release | H11: Lovetest | J11: Nguyễn Nhật Minh, Nguyễn Tuyết Oanh | K11: Trần Nguyệt Ánh | L11: Sprint 2 (6/5 - 6/19)
A12: 2026-06-01 11:14 | B12: TICKET-13089 | C12: Add rate/tracking rate | D12: Task | E12: Add rate/add feature/edit database | F12: done | J12: Nguyễn Nhật Minh | K12: Trần Nguyệt Ánh | P12: 4
A13: 2026-06-01 11:15 | B13: TICKET-13090 | C13: Edit databsae | D13: Task | E13: Add rate/add feature/edit database | F13: done | J13: Nguyễn Nhật Minh | K13: Trần Nguyệt Ánh | P13: 3
A14: 2026-06-01 11:31 | B14: TICKET-13091 | C14: Bug 31. Với config đã liên kết app, nhấn vào pointer k hiện popup chỉnh sửa thông số pointer | D14: Bug | E14: V. Multi- action scripting | F14: done | J14: Trần Đức An | K14: Linh Đặng
A15: 2026-06-01 11:40 | B15: TICKET-13092 | C15: Select language _ UI logo khác so với thiết kế | D15: Bug | E15: 1. Edit UI/ luồng | F15: done | J15: Ngọc Văn Linh | K15: Nguyễn Tuyết Oanh
A16: 2026-06-01 11:40 | B16: TICKET-13093 | C16: Select Language _ UI " Next" qua màn khác so với thiết kế | D16: Bug | E16: 1. Edit UI/ luồng | F16: done | J16: Ngọc Văn Linh | K16: Nguyễn Tuyết Oanh
A17: 2026-06-01 11:42 | B17: TICKET-13094 | C17: Select Language _ UI màu cờ trùng với màu nền | D17: Bug | E17: 1. Edit UI/ luồng | F17: need to be clean | J17: Ngọc Văn Linh | K17: Nguyễn Tuyết Oanh
A18: 2026-06-01 11:45 | B18: TICKET-13097 | C18: Bug 32. Với config đã liên kết app, khi đã có pointer1, nhấn Swipe thêm thực thể vuốt mất pointer đã có và thêm thực thể vuốt từ luôn số 1 | D18: Bug | E18: V. Multi- action scripting | F18: done | J18: Trần Đức An | K18: Linh Đặng
A19: 2026-06-01 11:55 | B19: TICKET-13098 | C19: Bug 33. Play config chưa liên kết app từ ds existing script k chuyển hướng đúng màn | D19: Bug | E19: V. Multi- action scripting | F19: done | J19: Trần Đức An | K19: Linh Đặng
A20: 2026-06-01 12:00 | B20: TICKET-13100 | C20: Add flow no internet | D20: Task | F20: ready to progress | H20: Prank sound | K20: Trần Nguyệt Ánh
A21: 2026-06-01 12:03 | B21: TICKET-13102 | C21: 1.0.2 Add rate/ add feature/edit flow | D21: Task | F21: ready to release | H21: wallpaper | J21: Bùi Văn Tiến, Linh Đặng | K21: Trần Nguyệt Ánh | L21: Sprint 3 (6/22 - 7/3)
A22: 2026-06-01 13:36 | B22: TICKET-13103 | C22: Onboad _ UI text giới thiệu " Sound Prank" tại ngôn ngữ Vietnamese | D22: Bug | E22: 1. Edit UI/ luồng | F22: need to be clean | J22: Ngọc Văn Linh | K22: Nguyễn Tuyết Oanh
A23: 2026-06-01 13:41 | B23: TICKET-13104 | C23: IAP_ Không hiển thị ngôn ngữ theo language user select | D23: Bug | E23: 1. Edit UI/ luồng | F23: done | J23: Ngọc Văn Linh | K23: Nguyễn Tuyết Oanh
A24: 2026-06-01 13:46 | B24: TICKET-13105 | C24: IAP_ Hiển thị giá trị tiền tệ khác thiết kế | D24: Bug | E24: 1. Edit UI/ luồng | F24: need to be clean | J24: Ngọc Văn Linh | K24: Nguyễn Tuyết Oanh
A25: 2026-06-01 13:53 | B25: TICKET-13110 | C25: Call _ Hiển thị sai với danh sách Sound rỗng | D25: Bug | E25: 1. Edit UI/ luồng | F25: need to be clean | J25: Ngọc Văn Linh | K25: Nguyễn Tuyết Oanh
A26: 2026-06-01 14:00 | B26: TICKET-13112 | C26: Bug 34. Với config đã liên kết app, Chưa thực hiện thao tác vuốt theo cài đặt | D26: Bug | E26: V. Multi- action scripting | F26: done | J26: Trần Đức An | K26: Linh Đặng
A27: 2026-06-01 14:00 | B27: TICKET-13113 | C27: Bug 35. Play kịch bản đã liên kết app, thêm thao tác vuốt, nhấn play k chuyển trạng thái và hoạt động | D27: Bug | E27: V. Multi- action scripting | F27: done | J27: Trần Đức An | K27: Linh Đặng
A28: 2026-06-01 14:17 | B28: TICKET-13114 | C28: 38. view-wlp_between: Qc ko request mới khi lướt tới content trước qc native full | D28: Task | E28: Đã fix | F28: done | J28: Bùi Văn Tiến | K28: Kim Ngọc
A29: 2026-06-01 14:21 | B29: TICKET-13115 | C29: Bug 36. Với config đã liên kết app, k trừ được hết các điểm | D29: Bug | E29: V. Multi- action scripting | F29: done | J29: Trần Đức An | K29: Linh Đặng
A30: 2026-06-01 14:27 | B30: TICKET-13116 | C30: 39. view-wlp_between_native: Request sai kịch bản | D30: Task | E30: Đã fix | F30: done | J30: Bùi Văn Tiến | K30: Kim Ngọc
A31: 2026-06-01 14:32 | B31: TICKET-13117 | C31: 40. view-wlp_between_native: Sai logic hiển thị loading 2s | D31: Task | E31: Đã fix | F31: done | J31: Bùi Văn Tiến | K31: Kim Ngọc
A32: 2026-06-01 14:49 | B32: TICKET-13118 | C32: 41.view-wlp_between: Đã ẩn qc (inOn = false) nhưng vẫn hiện view loading ads | D32: Task | E32: Đã fix | F32: done | J32: Bùi Văn Tiến | K32: Kim Ngọc
A33: 2026-06-01 14:51 | B33: TICKET-13119 | C33: Call _ hiển thị sai danh sách khi có lỗi xảy ra | D33: Bug | E33: 1. Edit UI/ luồng | F33: done | J33: Ngọc Văn Linh | K33: Nguyễn Tuyết Oanh
... A35: 2026-06-01 17:46 | B35: TICKET-13189 | C35: 42.list-wlp_choose_ct, home_choose_content, search_choose_color, search-result_choose_ct, search_choose_ct, tab-collection_choose_content : Show 2 lần qc khi click 2 content 1 lần | D35: Task | E35: Đã fix | F35: done | J35: Bùi Văn Tiến | K35: Kim Ngọc
A36: 2026-06-01 18:20 | B36: TICKET-13202 | C36: MO test | D36: Task | E36: QA Test | F36: done | K36: Nguyễn Ngọc Hạnh Ngân
A37: 2026-06-01 18:21 | B37: TICKET-13203 | C37: Bug 1: qc prv_recorded-bottom bị prv_recorded-middle nằm đè lên | D37: Task | E37: MO test | F37: done | J37: Ngọc Văn Linh | K37: Nguyễn Ngọc Hạnh Ngân
A38: 2026-06-01 18:24 | B38: TICKET-13204 | C38: Bug 2: "isCloseWhenClickCollapsible" không hoạt động | D38: Task | E38: MO test | F38: need to be clean | K38: Nguyễn Ngọc Hạnh Ngân
A39: 2026-06-01 18:42 | B39: TICKET-13205 | C39: Bug 3: listmusic-unselect và listmusic-selected bị đảo logic | D39: Task | E39: MO test | F39: need to be clean | K39: Nguyễn Ngọc Hạnh Ngân
A40: 2026-06-02 11:26 | B40: TICKET-13280 | C40: 43. Sửa lại config | D40: Task | E40: Đã fix | F40: done | J40: Bùi Văn Tiến | K40: Kim Ngọc
A41: 2026-06-02 14:13 | B41: TICKET-13401 | C41: 44. Fix llogic request lại sau X giây | D41: Task | E41: Đã fix | F41: done | J41: Bùi Văn Tiến | K41: Kim Ngọc
...

Sheet Tháng 7
A1: Ngày lên đơn | B1: ID | C1: Tên task | D1: Loại | E1: Task cha | F1: Trạng thái | G1: Ưu tiên | H1: App Name | I1: Task type | J1: Người làm | K1: Người tạo | L1: Sprint | M1: Start date | N1: Due date | O1: Ngày đóng | P1: Điểm | Q1: Đánh giá DEV | R1: Đánh giá Test
A2: 2026-07-01 09:36 | B2: TICKET-15683 | C2: Bug 3: Không hiện qc nằm giữa các chức năng trên màn home | D2: Bug | E2: Fix ads/ add ads | F2: done | J2: Nguyễn Nhật Minh | K2: Linh Đặng
A3: 2026-07-01 11:08 | B3: TICKET-15684 | C3: Bug 4: Nhấn vào qc PIP trong 1 giây đầu tiên xuất hiện vẫn mở trang quảng cáo | D3: Bug | E3: Fix ads/ add ads | F3: need to be clean | J3: Nguyễn Nhật Minh | K3: Linh Đặng
A4: 2026-07-01 14:21 | B4: TICKET-15688 | C4: Bug 5: Cài "isCloseWhenClick": false trong language 2.1 nhưng nhấn vào qc, back lại đóng qc luôn | D4: Bug | E4: Fix ads/ add ads | F4: done | J4: Nguyễn Nhật Minh | K4: Linh Đặng
A5: 2026-07-01 15:41 | B5: TICKET-15689 | C5: QA testing: | D5: Task | E5: MVP 1.0.0 - Game Emulator | F5: in progress | K5: Trịnh Thị Thơ
A6: 2026-07-01 15:42 | B6: TICKET-15690 | C6: 1. Thiếu hiển thị màn load chuyển ngôn ngữ | D6: Bug | E6: Language | F6: done | J6: Trần Đức An | K6: Nguyễn Tuyết Oanh
A7: 2026-07-01 15:50 | B7: TICKET-15691 | C7: 2. Onboard _ Lỗi hiển thị text giữa các màn onboard không đều | D7: Bug | E7: Onboard | F7: done | J7: Trần Đức An | K7: Nguyễn Tuyết Oanh
A8: 2026-07-01 15:58 | B8: TICKET-15692 | C8: 3. Home _ Lỗi hiển thị " Something went wrong" khi user vào màn home | D8: Bug | E8: Home | F8: done | J8: Trần Đức An | K8: Nguyễn Tuyết Oanh
A9: 2026-07-01 16:06 | B9: TICKET-15693 | C9: 4. Home _ Lỗi khi click vào icon setting | D9: Bug | E9: Home | F9: done | J9: Trần Đức An | K9: Nguyễn Tuyết Oanh
A10: 2026-07-01 16:11 | B10: TICKET-15694 | C10: 5. Home _ Điều chỉnh button " Try Again" | D10: Bug | E10: Home | F10: done | J10: Trần Đức An | K10: Nguyễn Tuyết Oanh
A11: 2026-07-01 16:15 | B11: TICKET-15695 | C11: 6. Home _ Lỗi không thể reload lại sau khi kết nối mạng | D11: Bug | E11: Home | F11: done | J11: Trần Đức An | K11: Nguyễn Tuyết Oanh
A12: 2026-07-01 16:22 | B12: TICKET-15696 | C12: Bug 6: Quảng cáo giữa các mode trên màn Manual Dust Remove | D12: Bug | E12: Fix ads/ add ads | F12: done | J12: Nguyễn Nhật Minh | K12: Linh Đặng
A13: 2026-07-01 16:31 | B13: TICKET-15697 | C13: 7. Home _ màn hình bị nhảy sau khi user click icon " Yêu thích" | D13: Bug | E13: Home | F13: done | J13: Trần Đức An | K13: Nguyễn Tuyết Oanh
A14: 2026-07-01 16:35 | B14: TICKET-15698 | C14: 8. Home _ Màu nền text của mỗi item đang bị sáng hơn so với thiết kế | D14: Bug | E14: Home | F14: done | J14: Trần Đức An | K14: Nguyễn Tuyết Oanh
A15: 2026-07-01 16:42 | B15: TICKET-15699 | C15: 9. Information_ Lỗi hiển thị với các item ảnh mặc định | D15: Bug | E15: Information | F15: done | J15: Trần Đức An | K15: Nguyễn Tuyết Oanh
A16: 2026-07-01 16:53 | B16: TICKET-15700 | C16: 10. Home _ Lỗi không hiển thị danh sách game | D16: Bug | E16: Home | F16: done | J16: Trần Đức An | K16: Nguyễn Tuyết Oanh
A17: 2026-07-01 16:58 | B17: TICKET-15701 | C17: 2. Quảng cáo | D17: Task | E17: QA Testing | F17: all issue | K17: Trịnh Thị Thơ
A18: 2026-07-01 17:00 | B18: TICKET-15702 | C18: Bug1: Màn Language check thiếu case. Click vào quảng cáo hiển thị Language1.2 | D18: Bug | E18: 2. Quảng cáo | F18: done | J18: Lục Tiến Đạt | K18: Trịnh Thị Thơ
A19: 2026-07-01 17:03 | B19: TICKET-15703 | C19: Bug 7. Quảng cáo PIP hiện sai vị trí trên màn đầu tiên, các màn sau mới hiện đúng vị trí cài trên remote | D19: Bug | E19: Fix ads/ add ads | F19: done | J19: Nguyễn Nhật Minh | K19: Linh Đặng
A20: 2026-07-01 17:04 | B20: TICKET-15704 | C20: 11. All game _ See more _/ Library lỗi giao diện | D20: Bug | E20: ALL Game | F20: done | J20: Trần Đức An | K20: Nguyễn Tuyết Oanh
A21: 2026-07-01 17:09 | B21: TICKET-15705 | C21: 12. All game _ Lỗi khi click " Try Again" | D21: Bug | E21: ALL Game | F21: done | J21: Trần Đức An | K21: Nguyễn Tuyết Oanh
A22: 2026-07-01 17:18 | B22: TICKET-15706 | C22: 13. Icon lỗi mạng không giống thiết kế ( vẫn chấp nhận được) | D22: Bug | E22: Home | F22: done | J22: Trần Đức An | K22: Nguyễn Tuyết Oanh
A23: 2026-07-01 17:26 | B23: TICKET-15707 | C23: Bug2: Onboard 2: Quảng cáo này được load trước ở dialog change language | D23: Bug | E23: 2. Quảng cáo | F23: done | J23: Lục Tiến Đạt | K23: Trịnh Thị Thơ
A24: 2026-07-01 17:29 | B24: TICKET-15708 | C24: Bug3: Luồng onboard full 1: Quảng cáo này được load trước ở dialog change language | D24: Bug | E24: 2. Quảng cáo | F24: done | J24: Lục Tiến Đạt | K24: Trịnh Thị Thơ
A25: 2026-07-01 17:31 | B25: TICKET-15709 | C25: Bug4: Onboard3: Quảng cáo này được load trước ở dialog change language. | D25: Bug | E25: 2. Quảng cáo | F25: done | J25: Lục Tiến Đạt | K25: Trịnh Thị Thơ
A26: 2026-07-01 17:34 | B26: TICKET-15710 | C26: 14. Search _ Lỗi hiển thị danh sách history results | D26: Bug | E26: Search | F26: done | J26: Trần Đức An | K26: Nguyễn Tuyết Oanh
A27: 2026-07-01 17:45 | B27: TICKET-15711 | C27: 15. Search _ Lỗi hiển thị danh sách results | D27: Bug | E27: Search | F27: done | J27: Trần Đức An | K27: Nguyễn Tuyết Oanh
A28: 2026-07-01 17:52 | B28: TICKET-15712 | C28: 16. Information _ Lỗi hiển thị, thao tác icon yêu thích tại các item | D28: Bug | E28: Information | F28: done | J28: Trần Đức An | K28: Nguyễn Tuyết Oanh
A29: 2026-07-02 09:55 | B29: TICKET-15716 | C29: 17. Store Game _ Hiển thị sai danh sách game | D29: Task | E29: Store game | F29: done | G29: normal | K29: Nguyễn Tuyết Oanh
A30: 2026-07-02 10:24 | B30: TICKET-15717 | C30: game pad | D30: Task | E30: play game | F30: done | J30: Trần Đức An | K30: Trần Đức An
A31: 2026-07-02 10:25 | B31: TICKET-15718 | C31: logic play game | D31: Task | E31: play game | F31: done | J31: Trần Đức An | K31: Trần Đức An
A32: 2026-07-02 10:31 | B32: TICKET-15719 | C32: 18. Library_ Lỗi hiển thị danh sách game tại Recent/ Your Game | D32: Task | E32: Library | F32: done | K32: Nguyễn Tuyết Oanh
A33: 2026-07-02 10:39 | B33: TICKET-15720 | C33: 19. Library _ Lỗi thiếu hiển thị danh sách game tại Favourite | D33: Task | E33: Library | F33: done | K33: Nguyễn Tuyết Oanh
A34: 2026-07-02 10:53 | B34: TICKET-15721 | C34: 20. Library _ Lỗi hiển thị sai tên màn hình | D34: Task | E34: Library | F34: done | K34: Nguyễn Tuyết Oanh
A35: 2026-07-02 10:58 | B35: TICKET-15722 | C35: 21. Store Game _ Lỗi hiển thị thông báo khi mất mạng | D35: Task | E35: Store game | F35: done | K35: Nguyễn Tuyết Oanh
A36: 2026-07-02 11:13 | B36: TICKET-15725 | C36: 23. Search _ Điều chỉnh phương thức tìm kiếm | D36: Task | E36: Search | F36: done | K36: Nguyễn Tuyết Oanh
A37: 2026-07-02 11:19 | B37: TICKET-15726 | C37: 24. Library_ Filter không active | D37: Task | E37: Library | F37: done | K37: Nguyễn Tuyết Oanh
A38: 2026-07-02 11:29 | B38: TICKET-15727 | C38: 25. Library -> Store game _ Lỗi hiển thị màn mất mạng | D38: Task | E38: Library | F38: done | K38: Nguyễn Tuyết Oanh
A39: 2026-07-02 11:47 | B39: TICKET-15729 | C39: Bug5: Quảng cáo colapsiable không click được : cả medium/text đều không click được. | D39: Bug | E39: 2. Quảng cáo | F39: done | J39: Lục Tiến Đạt | K39: Trịnh Thị Thơ
A40: 2026-07-02 13:45 | B40: TICKET-15732 | C40: 27. Information_ Một số game không hiển thị phần " Similar Games" | D40: Task | E40: Information | F40: done | K40: Nguyễn Tuyết Oanh
...

Sheet Tháng 8
A1: Ngày lên đơn | B1: ID | C1: Tên task | D1: Loại | E1: Task cha | F1: Trạng thái | G1: Ưu tiên | H1: App Name | I1: Task type | J1: Người làm | K1: Người tạo | L1: Sprint | M1: Start date | N1: Due date | O1: Ngày đóng | P1: Điểm | Q1: Đánh giá DEV | R1: Đánh giá Test
A2: 2026-08-01 14:37 | B2: TICKET-17256 | C2: QA testing: | D2: Task | E2: 1.0.1 - Add ads/ Add IAP | F2: all issue | K2: Trịnh Thị Thơ
A3: 2026-08-01 14:37 | B3: TICKET-17257 | C3: Add ads: | D3: Task | E3: QA testing: | F3: all issue | K3: Trịnh Thị Thơ
A4: 2026-08-01 14:40 | B4: TICKET-17258 | C4: Bug 1: Quảng cáo màn splash không hiển thị , không báo fail dev check lại các case | D4: Bug | E4: Add ads: | F4: done | J4: Trần Đức An | K4: Trịnh Thị Thơ
A5: 2026-08-01 14:55 | B5: TICKET-17259 | C5: Bug2: 2.1 :Quảng cáo language load trước tại splash. Hiện tại lại load ở màn language 2.1: Quảng cáo: language2.1 không show. Check lại | D5: Bug | E5: Add ads: | F5: done | J5: Trần Đức An | K5: Trịnh Thị Thơ
A6: 2026-08-01 18:01 | B6: TICKET-17260 | C6: Bug3: Quảng cáo inter thiếu text: ad ở góc màn hình | D6: Bug | E6: Add ads: | F6: done | J6: Trần Đức An | K6: Trịnh Thị Thơ
A7: 2026-08-01 18:03 | B7: TICKET-17261 | C7: Bug4: Quảng cáo banner Home thiếu text: Ad ở góc màn hình | D7: Bug | E7: Add ads: | F7: done | J7: Trần Đức An | K7: Trịnh Thị Thơ
A8: 2026-08-01 23:12 | B8: TICKET-17262 | C8: Bug5: Quảng cáo Open ads chưa show check lại | D8: Bug | E8: Add ads: | F8: done | J8: Trần Đức An | K8: Trịnh Thị Thơ
A9: 2026-08-01 23:44 | B9: TICKET-17263 | C9: Bug6: Add game: Quảng cáo dưới chân màn: thuộc tính "isCloseWhenClick": true, nhưng quảng cáo vẫn hiện không mất đi khi click vào. | D9: Bug | E9: Add ads: | F9: done | J9: Trần Đức An | K9: Trịnh Thị Thơ
A10: 2026-08-02 12:30 | B10: TICKET-17264 | C10: Bug7: Native full sau splash inter không click được (video) | D10: Bug | E10: Add ads: | F10: done | J10: Trần Đức An | K10: Trịnh Thị Thơ
A11: 2026-08-02 15:35 | B11: TICKET-17268 | C11: Bug8: Click game :Chưa có :Timeout xs remote config default 5s | D11: Bug | E11: Add ads: | F11: done | J11: Trần Đức An | K11: Trịnh Thị Thơ
A12: 2026-08-02 17:40 | B12: TICKET-17273 | C12: Bug9: search_bottom : Không có data không hiện quảng cáo. | D12: Bug | E12: Add ads: | F12: done | J12: Trần Đức An | K12: Trịnh Thị Thơ
A13: 2026-08-02 17:56 | B13: TICKET-17274 | C13: Bug10: Click exit/restart popup confirm=>> Click button exit/restart mới load show quảng cáo . Đây đang show trước | D13: Bug | E13: Add ads: | F13: done | J13: Trần Đức An | K13: Trịnh Thị Thơ
A14: 2026-08-02 18:01 | B14: TICKET-17275 | C14: Bug11: Ads bottom : trên fire base : "isPreloadAfterShow": true, mà không load lại | D14: Bug | E14: Add ads: | F14: done | J14: Trần Đức An | K14: Trịnh Thị Thơ
A15: 2026-08-02 18:27 | B15: TICKET-17276 | C15: Bug12: Check lại : Click Download Reward: để đúng định dạng nhưng không show | D15: Bug | E15: Add ads: | F15: done | J15: Trần Đức An | K15: Trịnh Thị Thơ
A16: 2026-08-02 18:30 | B16: TICKET-17277 | C16: Bug13: Click Download Inter: Để định dạng : "type": "interstitial", nhưng vẫn hiện dailog reward.(video) | D16: Bug | E16: Add ads: | F16: done | J16: Trần Đức An | K16: Trịnh Thị Thơ
A17: 2026-08-03 09:31 | B17: TICKET-17278 | C17: 1.0.0 phiên bản MVP | D17: Task | F17: done | H17: spin wheel 2 | J17: Ngọc Văn Linh | K17: Lục Tiến Đạt | L17: Sprint 2 (7/28 - 8/31)
A18: 2026-08-03 09:34 | B18: TICKET-17279 | C18: Luồng đầu vào + màn Setting | D18: Task | E18: 1.0.0 phiên bản MVP | F18: done | J18: Bùi Văn Tiến | K18: Bùi Văn Tiến | P18: 2
A19: 2026-08-03 09:36 | B19: TICKET-17280 | C19: (Game Assistant) Màn Game Assistant | D19: Task | E19: 1.0.0 phiên bản MVP | F19: done | J19: Bùi Văn Tiến | K19: Bùi Văn Tiến | P19: 2
A20: 2026-08-03 09:37 | B20: TICKET-17281 | C20: Màn Apps | D20: Task | E20: (Game Assistant) Màn Game Assistant | F20: done | J20: Bùi Văn Tiến, Ngọc Văn Linh | K20: Bùi Văn Tiến
A21: 2026-08-03 09:37 | B21: TICKET-17282 | C21: Màn System | D21: Task | E21: (Game Assistant) Màn Game Assistant | F21: done | J21: Bùi Văn Tiến, Ngọc Văn Linh | K21: Bùi Văn Tiến
A22: 2026-08-03 09:39 | B22: TICKET-17283 | C22: (Game Assistant) Màn Configure Game Optimizations | D22: Task | E22: 1.0.0 phiên bản MVP | F22: done | J22: Bùi Văn Tiến | K22: Bùi Văn Tiến | P22: 4
A23: 2026-08-03 09:40 | B23: TICKET-17284 | C23: (Game Assistant) Màn Optimizing Game | D23: Task | E23: 1.0.0 phiên bản MVP | F23: done | J23: Bùi Văn Tiến | K23: Bùi Văn Tiến | P23: 2
A24: 2026-08-03 09:40 | B24: TICKET-17285 | C24: (Game Hub) Màn Game Hub | D24: Task | E24: 1.0.0 phiên bản MVP | F24: done | J24: Bùi Văn Tiến | K24: Bùi Văn Tiến | P24: 1.5
A25: 2026-08-03 09:41 | B25: TICKET-17287 | C25: (Game Hub) Màn Game Fit Score | D25: Task | E25: 1.0.0 phiên bản MVP | F25: done | J25: Bùi Văn Tiến | K25: Bùi Văn Tiến | P25: 1.5
A26: 2026-08-03 09:41 | B26: TICKET-17286 | C26: (Game Hub) Màn Game Rescore | D26: Task | E26: 1.0.0 phiên bản MVP | F26: done | J26: Bùi Văn Tiến | K26: Bùi Văn Tiến | P26: 2
A27: 2026-08-03 09:42 | B27: TICKET-17288 | C27: (Game Hub) Màn Analyzing Game Fit | D27: Task | E27: 1.0.0 phiên bản MVP | F27: done | J27: Bùi Văn Tiến | K27: Bùi Văn Tiến | P27: 3.5
A28: 2026-08-03 09:43 | B28: TICKET-17289 | C28: (Game Hub) Màn Performance Analysis | D28: Task | E28: 1.0.0 phiên bản MVP | F28: done | J28: Bùi Văn Tiến | K28: Bùi Văn Tiến | P28: 4
A29: 2026-08-03 09:44 | B29: TICKET-17290 | C29: [GAME MODE 3]Nghiên cứu tối ưu kỹ thuật | D29: Task | F29: done | H29: Game mode 3 | J29: Lỗ Thành Duy | K29: Dương Thế Tài | L29: Sprint 2 (7/28 - 8/31) | M29: 2026-08-03 09:00 | N29: 2026-08-31 18:00
A30: 2026-08-03 09:44 | B30: TICKET-17291 | C30: (Game Hub) Màn Graphics Optimizer | D30: Task | E30: 1.0.0 phiên bản MVP | F30: done | J30: Bùi Văn Tiến | K30: Bùi Văn Tiến | P30: 5
A31: 2026-08-03 09:44 | B31: TICKET-17292 | C31: (Game Hub) Màn Optimize Complete | D31: Task | E31: 1.0.0 phiên bản MVP | F31: done | K31: Bùi Văn Tiến | P31: 1
A32: 2026-08-03 09:45 | B32: TICKET-17293 | C32: Màn Basic Optimize | D32: Task | E32: (Game Hub) Màn Graphics Optimizer | F32: done | J32: Bùi Văn Tiến, Ngọc Văn Linh | K32: Bùi Văn Tiến
A33: 2026-08-03 09:45 | B33: TICKET-17294 | C33: Màn Enhance Optimize | D33: Task | E33: (Game Hub) Màn Graphics Optimizer | F33: done | J33: Bùi Văn Tiến, Ngọc Văn Linh | K33: Bùi Văn Tiến
A34: 2026-08-03 09:45 | B34: TICKET-17295 | C34: (Game Hub) Màn Add Widget | D34: Task | E34: 1.0.0 phiên bản MVP | F34: done | K34: Bùi Văn Tiến | P34: 3
A35: 2026-08-03 09:46 | B35: TICKET-17296 | C35: (Game Hub) Màn List Tips Game | D35: Task | E35: 1.0.0 phiên bản MVP | F35: done | K35: Bùi Văn Tiến | P35: 2
A36: 2026-08-03 09:46 | B36: TICKET-17297 | C36: (Game Hub) Màn Tip Game Detail | D36: Task | E36: 1.0.0 phiên bản MVP | F36: done | K36: Bùi Văn Tiến | P36: 3
A37: 2026-08-03 09:46 | B37: TICKET-17298 | C37: (VPN) Màn Connect VPN | D37: Task | E37: 1.0.0 phiên bản MVP | F37: pending | K37: Bùi Văn Tiến
A38: 2026-08-03 09:48 | B38: TICKET-17301 | C38: (VPN) Màn Select Server | D38: Task | E38: 1.0.0 phiên bản MVP | F38: pending | K38: Bùi Văn Tiến
A39: 2026-08-03 09:49 | B39: TICKET-17299 | C39: (VPN) Màn Connection Detail | D39: Task | E39: 1.0.0 phiên bản MVP | F39: pending | K39: Bùi Văn Tiến
A40: 2026-08-03 09:50 | B40: TICKET-17300 | C40: (VPN) Các màn liên quan đến xin quyền VPN | D40: Task | E40: 1.0.0 phiên bản MVP | F40: pending | K40: Bùi Văn Tiến
...

Sheet Tháng 9
A1: Ngày lên đơn | B1: ID | C1: Tên task | D1: Loại | E1: Task cha | F1: Trạng thái | G1: Ưu tiên | H1: App Name | I1: Task type | J1: Người làm | K1: Người tạo | L1: Sprint | M1: Start date | N1: Due date | O1: Ngày đóng | P1: Điểm | Q1: Đánh giá DEV | R1: Đánh giá Test
A2: 2026-09-01 21:20 | B2: TICKET-21890 | C2: Qa: Testing: | D2: Task | E2: 1.1.9 - Fix ads/Fix luồng | F2: all issue | J2: Trịnh Thị Thơ | K2: Trịnh Thị Thơ | P2: 16
A3: 2026-09-01 21:21 | B3: TICKET-21891 | C3: Fix luồng: | D3: Task | E3: Qa: Testing: | F3: all issue | J3: Trịnh Thị Thơ | K3: Trịnh Thị Thơ | P3: 13
A4: 2026-09-01 21:21 | B4: TICKET-21892 | C4: Bug1: nhỏ (btnContinueV2) ở góc trên bên phải toolbar. | D4: Bug | E4: Fix luồng: | F4: done | J4: Nguyễn Nhật Minh | K4: Trịnh Thị Thơ
A5: 2026-09-02 08:14 | B5: TICKET-21893 | C5: Fix ads: | D5: Task | E5: Qa: Testing: | F5: all issue | J5: Trịnh Thị Thơ | K5: Trịnh Thị Thơ | P5: 3
A6: 2026-09-02 08:22 | B6: TICKET-21894 | C6: Bug1: Quảng cáo pic: Thoát ra vào lại không hiện quảng cáo =>MM: Thoát ra vào lại vẫn hiện quảng cáo | D6: Bug | E6: Fix ads: | F6: done | J6: Nguyễn Nhật Minh | K6: Trịnh Thị Thơ
A7: 2026-09-02 15:48 | B7: TICKET-21895 | C7: Bug2: Quảng cáo pic đè lên quảng cáo inter=>MM: Quảng cáo pic không đè lên inter | D7: Bug | E7: Fix ads: | F7: done | J7: Nguyễn Nhật Minh | K7: Trịnh Thị Thơ
A8: 2026-09-02 17:25 | B8: TICKET-21896 | C8: Bug3: Click vào :QC: money-spinning1_native thì hiển thị money-spinning2_native (xem video đính kèm) | D8: Bug | E8: Fix ads: | F8: qa - need fix | J8: Trần Đức An | K8: Trịnh Thị Thơ
A9: 2026-09-03 09:02 | B9: TICKET-21897 | C9: Triển khai tính năng 'Storage Dashboard' | D9: Task | E9: Nghiên cứu tính năng Phone cleaner | F9: done | J9: Lỗ Thành Duy | K9: Lỗ Thành Duy | N9: 2026-09-04 18:00 | P9: 0.67
A10: 2026-09-03 09:02 | B10: TICKET-21898 | C10: Triển khai tính năng 'Junk Clean' | D10: Task | E10: Nghiên cứu tính năng Phone cleaner | F10: done | J10: Lỗ Thành Duy | K10: Lỗ Thành Duy | N10: 2026-09-04 18:00 | P10: 3.67
A11: 2026-09-03 09:03 | B11: TICKET-21899 | C11: Triển khai tính năng 'Device Performance' | D11: Task | E11: Nghiên cứu tính năng Phone cleaner | F11: done | J11: Lỗ Thành Duy | K11: Lỗ Thành Duy | N11: 2026-09-04 18:00 | P11: 0.67
A12: 2026-09-03 09:03 | B12: TICKET-21900 | C12: System cache | D12: Task | E12: Triển khai tính năng 'Junk Clean' | F12: done | J12: Lỗ Thành Duy | K12: Lỗ Thành Duy
A13: 2026-09-03 09:03 | B13: TICKET-21901 | C13: Residual file | D13: Task | E13: Triển khai tính năng 'Junk Clean' | F13: done | J13: Lỗ Thành Duy | K13: Lỗ Thành Duy
A14: 2026-09-03 09:04 | B14: TICKET-21902 | C14: Temporary files | D14: Task | E14: Triển khai tính năng 'Junk Clean' | F14: done | J14: Lỗ Thành Duy | K14: Lỗ Thành Duy
A15: 2026-09-03 09:14 | B15: TICKET-21903 | C15: File Manager | D15: Task | E15: Nghiên cứu tính năng Phone cleaner | F15: done | J15: Lỗ Thành Duy | K15: Lỗ Thành Duy | N15: 2026-09-08 18:00 | P15: 2.67
A16: 2026-09-03 09:14 | B16: TICKET-21904 | C16: App Manager | D16: Task | E16: Nghiên cứu tính năng Phone cleaner | F16: done | J16: Lỗ Thành Duy | K16: Lỗ Thành Duy | N16: 2026-09-08 18:00 | P16: 2.33
A17: 2026-09-03 09:14 | B17: TICKET-21905 | C17: Cloud (Pending trong bản đầu) | D17: Task | E17: Nghiên cứu tính năng Phone cleaner | F17: pending | J17: Lỗ Thành Duy | K17: Lỗ Thành Duy
A18: 2026-09-03 09:14 | B18: TICKET-21906 | C18: Recyclebin | D18: Task | E18: Nghiên cứu tính năng Phone cleaner | F18: done | J18: Lỗ Thành Duy | K18: Lỗ Thành Duy | N18: 2026-09-11 18:00 | P18: 10
A19: 2026-09-03 09:27 | B19: TICKET-21907 | C19: Nghiên cứu tính năng tương tác với model/mini game/duble model/change skin | D19: Task | F19: done | H19: AR Dog | J19: Lỗ Thành Duy, Ngọc Văn Linh | K19: Trần Nguyệt Ánh | L19: Sprint 3 (9/3 - 9/30) | N19: 2026-09-18 18:00
